<?xml version="1.0"?>
<robot name="2dof_robot_arm_assembly" xmlns:xacro="http://www.ros.org/wiki/xacro">

<xacro:include filename="$(find 2dof_robot_arm_assembly_description)/urdf/materials.xacro" />
<xacro:include filename="$(find 2dof_robot_arm_assembly_description)/urdf/2dof_robot_arm_assembly.trans" />
<xacro:include filename="$(find 2dof_robot_arm_assembly_description)/urdf/2dof_robot_arm_assembly.gazebo" />
<link name="dummy"/>

<link name="base_link">
  <inertial>
    <origin xyz="-1.5131464107709274e-17 -7.565732053854637e-18 0.01669022341463877" rpy="0 0 0"/>
    <mass value="2.359168074581756"/>
    <inertia ixx="0.001913" iyy="0.001913" izz="0.003248" ixy="-0.0" iyz="-0.0" ixz="-0.0"/>
  </inertial>
  <visual>
    <origin xyz="0 0 0" rpy="0 0 0"/>
    <geometry>
      <mesh filename="package://2dof_robot_arm_assembly_description/meshes/base_link.stl" scale="0.001 0.001 0.001"/>
    </geometry>
    <material name="steel_satin"/>
  </visual>
  <collision>
    <origin xyz="0 0 0" rpy="0 0 0"/>
    <geometry>
      <mesh filename="package://2dof_robot_arm_assembly_description/meshes/base_link.stl" scale="0.001 0.001 0.001"/>
    </geometry>
  </collision>
</link>

<link name="link1_v3_1">
  <inertial>
    <origin xyz="2.9107983085076832e-15 3.270648008693948e-16 0.013727359835796218" rpy="0 0 0"/>
    <mass value="0.44267396683570365"/>
    <inertia ixx="0.000161" iyy="0.000142" izz="0.000219" ixy="2e-06" iyz="-0.0" ixz="-0.0"/>
  </inertial>
  <visual>
    <origin xyz="-0.0 -0.0 -0.04" rpy="0 0 0"/>
    <geometry>
      <mesh filename="package://2dof_robot_arm_assembly_description/meshes/link1_v3_1.stl" scale="0.001 0.001 0.001"/>
    </geometry>
    <material name="steel_satin"/>
  </visual>
  <collision>
    <origin xyz="-0.0 -0.0 -0.04" rpy="0 0 0"/>
    <geometry>
      <mesh filename="package://2dof_robot_arm_assembly_description/meshes/link1_v3_1.stl" scale="0.001 0.001 0.001"/>
    </geometry>
  </collision>
</link>

<link name="link2_v1_1">
  <inertial>
    <origin xyz="0.03538420026546515 0.01397606643689022 0.03395004014093726" rpy="0 0 0"/>
    <mass value="0.2786576290786893"/>
    <inertia ixx="0.000174" iyy="0.000361" izz="0.000196" ixy="-2.1e-05" iyz="-1.8e-05" ixz="-0.000159"/>
  </inertial>
  <visual>
    <origin xyz="-0.0011 0.009939 -0.07" rpy="0 0 0"/>
    <geometry>
      <mesh filename="package://2dof_robot_arm_assembly_description/meshes/link2_v1_1.stl" scale="0.001 0.001 0.001"/>
    </geometry>
    <material name="steel_satin"/>
  </visual>
  <collision>
    <origin xyz="-0.0011 0.009939 -0.07" rpy="0 0 0"/>
    <geometry>
      <mesh filename="package://2dof_robot_arm_assembly_description/meshes/link2_v1_1.stl" scale="0.001 0.001 0.001"/>
    </geometry>
  </collision>
</link>

<link name="end_effector_v2_1">
  <inertial>
    <origin xyz="0.04039450367126857 -0.0005610191776430004 -0.022568541174821127" rpy="0 0 0"/>
    <mass value="0.5633553038394754"/>
    <inertia ixx="0.000164" iyy="0.00039" izz="0.000322" ixy="-2.5e-05" iyz="1.5e-05" ixz="0.000132"/>
  </inertial>
  <visual>
    <origin xyz="-0.072418 -0.013044 -0.1379" rpy="0 0 0"/>
    <geometry>
      <mesh filename="package://2dof_robot_arm_assembly_description/meshes/end_effector_v2_1.stl" scale="0.001 0.001 0.001"/>
    </geometry>
    <material name="steel_satin"/>
  </visual>
  <collision>
    <origin xyz="-0.072418 -0.013044 -0.1379" rpy="0 0 0"/>
    <geometry>
      <mesh filename="package://2dof_robot_arm_assembly_description/meshes/end_effector_v2_1.stl" scale="0.001 0.001 0.001"/>
    </geometry>
  </collision>
</link>

<joint name="dummy_joint" type="fixed">
  <origin xyz="0.0 0.0 0.2" rpy="0 0 0"/>
  <parent link="dummy"/>
  <child link="base_link"/>
</joint>

<joint name="Rev1" type="continuous">
  <origin xyz="0.0 0.0 0.04" rpy="0 0 0"/>
  <parent link="base_link"/>
  <child link="link1_v3_1"/>
  <axis xyz="0.0 0.0 1.0"/>
</joint>

<joint name="Rev2" type="revolute">
  <origin xyz="0.0011 -0.009939 0.03" rpy="0 0 0"/>
  <parent link="link1_v3_1"/>
  <child link="link2_v1_1"/>
  <axis xyz="0.109981 -0.993934 -0.0"/>
  <limit upper="2.1" lower="-0.3" effort="100" velocity="100"/>
</joint>

<joint name="Rev3" type="revolute">
  <origin xyz="0.071318 0.022983 0.0679" rpy="0 0 0"/>
  <parent link="link2_v1_1"/>
  <child link="end_effector_v2_1"/>
  <axis xyz="-0.109981 0.993934 0.0"/>
  <limit upper="6.283185" lower="3.141593" effort="100" velocity="100"/>
</joint>

</robot>
